<?xml version="1.0" ?>
<robot name="demo02" xmlns:xacro="http://ros.org/wiki/xacro">

	<xacro:property name="base_link_length" value="0.103" />
	<xacro:property name="base_link_mass" value="125" /> 
	<xacro:property name="cylinder_link_mass" value="40" />

	<link name="base_footprint">
		<visual>
			<geometry>
				<sphere radius="0.001" />
			</geometry>
			<origin xyz="0.0 0.0 0" rpy="0 0 0" />
		</visual>
	</link>

	<joint name="link2footprint" type="fixed">
		<parent link="base_footprint" />
		<child link="base_link" />
		
		<origin xyz="0.0 0.0 0.0565" rpy="0 0 0" />
	</joint>	

  <link
    name="base_link">
    <inertial>
      
      <mass
        value="125" />
      <inertia
        ixx="0.81"
        ixy="0"
        ixz="0"
        iyy="2.43"
        iyz="0"
        izz="1.82" />
    </inertial>
    <visual>
      <origin
        xyz="0 0 0"
        rpy="0 0 0" />
      <geometry>
        <mesh
          filename="package://demo_gazebo/meshes/base_link.STL" />
      </geometry>
      <material
        name="">
        <color
          rgba="1 1 1 1" />
      </material>
    </visual>
    <collision>
      <origin
        xyz="0 0 0"
        rpy="0 0 0" />
      <geometry>
        <mesh
          filename="package://demo_gazebo/meshes/base_link.STL" />
      </geometry>
    </collision>
  </link>
  <link
    name="cylinder_link_1">
    <inertial>
      
      <mass
        value="40" />
      <inertia
        ixx="0.0085"
        ixy="0"
        ixz="0"
        iyy="0.0085"
        iyz="0"
        izz="0.0151" />
    </inertial>
    <visual>
      <origin
        xyz="0 0 0"
        rpy="0 0 0" />
      <geometry>
        <mesh
          filename="package://demo_gazebo/meshes/cylinder_link_1.STL" />
      </geometry>
      <material
        name="">
        <color
          rgba="0.792156862745098 0.819607843137255 0.933333333333333 1" />
      </material>
    </visual>
    <collision>
      <origin
        xyz="0 0 0"
        rpy="0 0 0" />
      <geometry>
        <mesh
          filename="package://demo_gazebo/meshes/cylinder_link_1.STL" />
      </geometry>
    </collision>
  </link>
  <joint
    name="base_cylinder_1"
    type="continuous">
    <origin
      xyz="0.12445 0.139 0.0368"
      rpy="0 0 0" />
    <parent
      link="base_link" />
    <child
      link="cylinder_link_1" />
    <axis
      xyz="0 1 0" />
  </joint>
  <link
    name="cylinder_link_2">
    <inertial>
      
      <mass
        value="40" />
      <inertia
        ixx="0.0085"
        ixy="0"
        ixz="0"
        iyy="0.0085"
        iyz="0"
        izz="0.0151" />
    </inertial>
    <visual>
      <origin
        xyz="0 0 0"
        rpy="0 0 0" />
      <geometry>
        <mesh
          filename="package://demo_gazebo/meshes/cylinder_link_2.STL" />
      </geometry>
      <material
        name="">
        <color
          rgba="0.792156862745098 0.819607843137255 0.933333333333333 1" />
      </material>
    </visual>
    <collision>
      <origin
        xyz="0 0 0"
        rpy="0 0 0" />
      <geometry>
        <mesh
          filename="package://demo_gazebo/meshes/cylinder_link_2.STL" />
      </geometry>
    </collision>
  </link>
  <joint
    name="base_cylinder_2"
    type="continuous">
    <origin
      xyz="0.12445 -0.058 0.0368"
      rpy="0 0 0" />
    <parent
      link="base_link" />
    <child
      link="cylinder_link_2" />
    <axis
      xyz="0 1 0" />
  </joint>
  <link
    name="cylinder_link_3">
    <inertial>
      <mass
        value="40" />
      <inertia
        ixx="0.0085"
        ixy="0"
        ixz="0"
        iyy="0.0085"
        iyz="0"
        izz="0.0151" />
    </inertial>
    <visual>
      <origin
        xyz="0 0 0"
        rpy="0 0 0" />
      <geometry>
        <mesh
          filename="package://demo_gazebo/meshes/cylinder_link_3.STL" />
      </geometry>
      <material
        name="">
        <color
          rgba="0.792156862745098 0.819607843137255 0.933333333333333 1" />
      </material>
    </visual>
    <collision>
      <origin
        xyz="0 0 0"
        rpy="0 0 0" />
      <geometry>
        <mesh
          filename="package://demo_gazebo/meshes/cylinder_link_3.STL" />
      </geometry>
    </collision>
  </link>
  <joint
    name="base_cylinder_3"
    type="continuous">
    <origin
      xyz="-0.12445 -0.054 0.0368"
      rpy="0 0 0" />
    <parent
      link="base_link" />
    <child
      link="cylinder_link_3" />
    <axis
      xyz="0 1 0" />
  </joint>
  <link
    name="cylinder_link_4">
    <inertial>
      <mass
        value="40" />
      <inertia
        ixx="0.0085"
        ixy="0"
        ixz="0"
        iyy="0.0085"
        iyz="0"
        izz="0.0151" />
    </inertial>
    <visual>
      <origin
        xyz="0 0 0"
        rpy="0 0 0" />
      <geometry>
        <mesh
          filename="package://demo_gazebo/meshes/cylinder_link_4.STL" />
      </geometry>
      <material
        name="">
        <color
          rgba="0.792156862745098 0.819607843137255 0.933333333333333 1" />
      </material>
    </visual>
    <collision>
      <origin
        xyz="0 0 0"
        rpy="0 0 0" />
      <geometry>
        <mesh
          filename="package://demo_gazebo/meshes/cylinder_link_4.STL" />
      </geometry>
    </collision>
  </link>
  <joint
    name="base_cylinder_4"
    type="continuous">
    <origin
      xyz="-0.12445 0.144 0.0368"
      rpy="0 0 0" />
    <parent
      link="base_link" />
    <child
      link="cylinder_link_4" />
    <axis
      xyz="0 1 0" />
  </joint>
</robot>
